Workbook

Sheet Register Map
A1: CAN 2.0B Controller: Register Map
A2: Source: CAN 2.0B Controller Design Specification, Section 5 (Register Map); notes from Sections 6, 9 and 10. APB4 slave can_apb_slave, ADDR_WIDTH = 12, all registers 32 bits, word aligned, 0x000 to 0x068.
A3: Reset value and field count are formulas driven by the Fields sheet. Write-only registers read as 0.
A5: Offset | B5: Register | C5: Access | D5: Group | E5: Reset value | F5: Fields | G5: Description | H5: Write rejected with PSLVERR when | I5: Spec section
A6: 0x000 | B6: VERSION | C6: RO | D6: Identification / control | E6: ="0x"&DEC2HEX(SUMPRODUCT((Fields!$A$2:$A$72=$A6)*Fields!$J$2:$J$72*2^Fields!$F$2:$F$72),8) -> 0x01002001 | F6: =COUNTIFS(Fields!$A$2:$A$72,$A6,Fields!$K$2:$K$72,"No") -> 1 | G6: Fixed identification / version code. | H6: - | I6: -
A7: 0x004 | B7: CONTROL | C7: RW | D7: Identification / control | E7: ="0x"&DEC2HEX(SUMPRODUCT((Fields!$A$2:$A$72=$A7)*Fields!$J$2:$J$72*2^Fields!$F$2:$F$72),8) -> 0x00000000 | F7: =COUNTIFS(Fields!$A$2:$A$72,$A7,Fields!$K$2:$K$72,"No") -> 3 | G7: Core enable, loopback and listen-only mode bits. | H7: Clearing CAN_ENABLE while a frame is in progress (tx_busy); setting LOOPBACK and LISTEN_ONLY together in one write. | I7: 5, 6.9
A8: 0x008 | B8: STATUS | C8: RO | D8: Status | E8: ="0x"&DEC2HEX(SUMPRODUCT((Fields!$A$2:$A$72=$A8)*Fields!$J$2:$J$72*2^Fields!$F$2:$F$72),8) -> 0x00000000 | F8: =COUNTIFS(Fields!$A$2:$A$72,$A8,Fields!$K$2:$K$72,"No") -> 11 | G8: Bus busy, TX done, RX FIFO flags, live error pulses, sticky RX overflow. | H8: - | I8: 5, 10
A9: 0x00C | B9: ERROR_STATUS | C9: RO | D9: Status | E9: ="0x"&DEC2HEX(SUMPRODUCT((Fields!$A$2:$A$72=$A9)*Fields!$J$2:$J$72*2^Fields!$F$2:$F$72),8) -> 0x00000000 | F9: =COUNTIFS(Fields!$A$2:$A$72,$A9,Fields!$K$2:$K$72,"No") -> 4 | G9: Error state, bus-off recovery flag, last latched error / event. | H9: - | I9: 5, 6.8
A10: 0x010 | B10: BRP | C10: RW | D10: Bit timing | E10: ="0x"&DEC2HEX(SUMPRODUCT((Fields!$A$2:$A$72=$A10)*Fields!$J$2:$J$72*2^Fields!$F$2:$F$72),8) -> 0x00000000 | F10: =COUNTIFS(Fields!$A$2:$A$72,$A10,Fields!$K$2:$K$72,"No") -> 1 | G10: Baud-rate prescaler: one time quantum = BRP x can_clk periods. | H10: Any write while CAN_ENABLE = 1. | I10: 5, 6.1, 10
A11: 0x014 | B11: SEGMENTS | C11: RW | D11: Bit timing | E11: ="0x"&DEC2HEX(SUMPRODUCT((Fields!$A$2:$A$72=$A11)*Fields!$J$2:$J$72*2^Fields!$F$2:$F$72),8) -> 0x00000000 | F11: =COUNTIFS(Fields!$A$2:$A$72,$A11,Fields!$K$2:$K$72,"No") -> 3 | G11: PROP_SEG, PHASE_SEG1 and PHASE_SEG2 lengths in time quanta. | H11: Whole register rejected while CAN_ENABLE = 1. | I11: 5, 6.1
A12: 0x018 | B12: SJW_CONTROL | C12: RW | D12: Bit timing | E12: ="0x"&DEC2HEX(SUMPRODUCT((Fields!$A$2:$A$72=$A12)*Fields!$J$2:$J$72*2^Fields!$F$2:$F$72),8) -> 0x00000000 | F12: =COUNTIFS(Fields!$A$2:$A$72,$A12,Fields!$K$2:$K$72,"No") -> 1 | G12: Synchronization jump width (resynchronization limit). | H12: Any write while CAN_ENABLE = 1. | I12: 5, 6.1
A13: 0x01C | B13: TX_ID | C13: RW | D13: Transmit | E13: ="0x"&DEC2HEX(SUMPRODUCT((Fields!$A$2:$A$72=$A13)*Fields!$J$2:$J$72*2^Fields!$F$2:$F$72),8) -> 0x00000000 | F13: =COUNTIFS(Fields!$A$2:$A$72,$A13,Fields!$K$2:$K$72,"No") -> 1 | G13: Identifier of the frame to transmit next (11-bit or 29-bit). | H13: - | I13: 5, 6.2
A14: 0x020 | B14: TX_CTRL | C14: RW | D14: Transmit | E14: ="0x"&DEC2HEX(SUMPRODUCT((Fields!$A$2:$A$72=$A14)*Fields!$J$2:$J$72*2^Fields!$F$2:$F$72),8) -> 0x00000000 | F14: =COUNTIFS(Fields!$A$2:$A$72,$A14,Fields!$K$2:$K$72,"No") -> 3 | G14: TX frame type bits (IDE, RTR) and data length code. | H14: - | I14: 5, 6.2, 10
A15: 0x024 | B15: TX_DATA_LO | C15: RW | D15: Transmit | E15: ="0x"&DEC2HEX(SUMPRODUCT((Fields!$A$2:$A$72=$A15)*Fields!$J$2:$J$72*2^Fields!$F$2:$F$72),8) -> 0x00000000 | F15: =COUNTIFS(Fields!$A$2:$A$72,$A15,Fields!$K$2:$K$72,"No") -> 1 | G15: TX data holding register, lower 32 bits. | H15: - | I15: 5, 6.2
A16: 0x028 | B16: TX_DATA_HI | C16: RW | D16: Transmit | E16: ="0x"&DEC2HEX(SUMPRODUCT((Fields!$A$2:$A$72=$A16)*Fields!$J$2:$J$72*2^Fields!$F$2:$F$72),8) -> 0x00000000 | F16: =COUNTIFS(Fields!$A$2:$A$72,$A16,Fields!$K$2:$K$72,"No") -> 1 | G16: TX data holding register, upper 32 bits. | H16: - | I16: 5, 6.2
A17: 0x02C | B17: TX_COMMAND | C17: WO | D17: Transmit | E17: ="0x"&DEC2HEX(SUMPRODUCT((Fields!$A$2:$A$72=$A17)*Fields!$J$2:$J$72*2^Fields!$F$2:$F$72),8) -> 0x00000000 | F17: =COUNTIFS(Fields!$A$2:$A$72,$A17,Fields!$K$2:$K$72,"No") -> 1 | G17: Write 1 to submit the staged frame; clears TX_STATUS sticky bits. | H17: - | I17: 5
... A32: 0x068 | B32: REC | C32: RO | D32: Error counters | E32: ="0x"&DEC2HEX(SUMPRODUCT((Fields!$A$2:$A$72=$A32)*Fields!$J$2:$J$72*2^Fields!$F$2:$F$72),8) -> 0x00000000 | F32: =COUNTIFS(Fields!$A$2:$A$72,$A32,Fields!$K$2:$K$72,"No") -> 1 | G32: Receive error counter. | H32: - | I32: 5, 6.8
A34: Summary
B35: Registers | E35: =COUNTA(A6:A32) -> 27
B36: Read-write (RW) | E36: =COUNTIF(C6:C32,"RW") -> 14
B37: Read-only (RO) | E37: =COUNTIF(C6:C32,"RO") -> 11
B38: Write-only (WO) | E38: =COUNTIF(C6:C32,"WO") -> 2
B39: Defined fields (excluding reserved) | E39: =SUM(F6:F32) -> 58
B40: Registers locked while CAN_ENABLE = 1 | E40: =COUNTIF(H6:H32,"*while CAN_ENABLE = 1*") -> 9
B42: Locked: BRP, SEGMENTS, SJW_CONTROL and the six FILTER registers. CONTROL has its own PSLVERR rules (see Rules & Notes).
B44: Access colours
B45: RW
B46: RO
B47: WO

Sheet Fields
A1: Offset | B1: Register | C1: Bits | D1: Field | E1: MSB | F1: LSB | G1: Width | H1: Access | I1: Reset | J1: Reset value (decimal) | K1: Reserved? | L1: Description | M1: Notes (Sections 5, 6, 10)
A2: 0x000 | B2: VERSION | C2: 31:0 | D2: VERSION | E2: 31 | F2: 0 | G2: =E2-F2+1 -> 32 | H2: RO | I2: 0x0100_2001 | J2: 16785409 | K2: No | L2: Fixed, read-only identification / version code. Writes have no effect. | M2: -
A3: 0x004 | B3: CONTROL | C3: 0 | D3: CAN_ENABLE | E3: 0 | F3: 0 | G3: =E3-F3+1 -> 1 | H3: RW | I3: 0 | J3: 0 | K3: No | L3: 1 = enable the core (bit-timing engine and protocol FSM run); 0 = core held in IDLE / disabled. A write that clears this bit while a frame is in progress (tx_busy) is rejected with PSLVERR and the register is left unchanged. | M3: PSLVERR case
A4: 0x004 | B4: CONTROL | C4: 1 | D4: LOOPBACK | E4: 1 | F4: 1 | G4: =E4-F4+1 -> 1 | H4: RW | I4: 0 | J4: 0 | K4: No | L4: 1 = internal loopback mode (Section 6.9). | M4: -
A5: 0x004 | B5: CONTROL | C5: 2 | D5: LISTEN_ONLY | E5: 2 | F5: 2 | G5: =E5-F5+1 -> 1 | H5: RW | I5: 0 | J5: 0 | K5: No | L5: 1 = listen-only / monitor mode (Section 6.9). A single write that sets LOOPBACK and LISTEN_ONLY together is rejected with PSLVERR and the register is left unchanged. | M5: PSLVERR case
A6: 0x004 | B6: CONTROL | C6: 31:3 | D6: Reserved | E6: 31 | F6: 3 | G6: =E6-F6+1 -> 29 | H6: RO | I6: 0 | J6: 0 | K6: Yes | L6: Reads as 0. | M6: -
A7: 0x008 | B7: STATUS | C7: 0 | D7: TX_BUSY | E7: 0 | F7: 0 | G7: =E7-F7+1 -> 1 | H7: RO | I7: 0 | J7: 0 | K7: No | L7: Bus / line busy: a frame (TX or RX) is currently in progress. | M7: -
A8: 0x008 | B8: STATUS | C8: 1 | D8: TX_DONE | E8: 1 | F8: 1 | G8: =E8-F8+1 -> 1 | H8: RO | I8: 0 | J8: 0 | K8: No | L8: Sticky: a transmission completed since the last write to TX_COMMAND. Cleared by writing TX_COMMAND (Section 5). | M8: Sticky
A9: 0x008 | B9: STATUS | C9: 2 | D9: RX_AVAILABLE | E9: 2 | F9: 2 | G9: =E9-F9+1 -> 1 | H9: RO | I9: 0 | J9: 0 | K9: No | L9: RX FIFO holds at least one complete frame. | M9: -
A10: 0x008 | B10: STATUS | C10: 3 | D10: RX_FIFO_FULL | E10: 3 | F10: 3 | G10: =E10-F10+1 -> 1 | H10: RO | I10: 0 | J10: 0 | K10: No | L10: RX FIFO is full (pclk-domain flag from the async FIFO). | M10: -
A11: 0x008 | B11: STATUS | C11: 4 | D11: ARB_LOST | E11: 4 | F11: 4 | G11: =E11-F11+1 -> 1 | H11: RO | I11: 0 | J11: 0 | K11: No | L11: Live, single-cycle pulse: arbitration was lost on the most recent can_clk cycle in which it occurred. Not latched (see Section 10). | M11: Single-cycle pulse: a polling host can miss it (Section 10)
A12: 0x008 | B12: STATUS | C12: 5 | D12: ACK_ERROR | E12: 5 | F12: 5 | G12: =E12-F12+1 -> 1 | H12: RO | I12: 0 | J12: 0 | K12: No | L12: Live, single-cycle pulse (not latched). | M12: Single-cycle pulse (Section 10)
A13: 0x008 | B13: STATUS | C13: 6 | D13: CRC_ERROR | E13: 6 | F13: 6 | G13: =E13-F13+1 -> 1 | H13: RO | I13: 0 | J13: 0 | K13: No | L13: Live, single-cycle pulse (not latched). | M13: Single-cycle pulse (Section 10)
... A72: 0x068 | B72: REC | C72: 7:0 | D72: REC | E72: 7 | F72: 0 | G72: =E72-F72+1 -> 8 | H72: RO | I72: 0 | J72: 0 | K72: No | L72: Receive error counter (Section 6.8). | M72: Saturates at 255 (Section 6.8)
A74: Reset (text) is the value printed in the spec; Reset value (decimal) is its numeric form used by the Register Map formulas. TX_START and RX_POP are write-only: no reset is listed in the spec and they read as 0.

Sheet Bit Map
A1: Bit map (bit 31 on the left, bit 0 on the right)
C2: RW field | I2: RO field | O2: WO field | U2: Reserved (reads 0) | AA2: Bits not listed in the spec table
A4: Offset | B4: Register | C4: 31 | D4: 30 | E4: 29 | F4: 28 | G4: 27 | H4: 26 | I4: 25 | J4: 24 | K4: 23 | L4: 22 | M4: 21 | N4: 20 | O4: 19 | P4: 18 | Q4: 17 | R4: 16 | S4: 15 | T4: 14 | U4: 13 | V4: 12 | W4: 11 | X4: 10 | Y4: 9 | Z4: 8 | AA4: 7 | AB4: 6 | AC4: 5 | AD4: 4 | AE4: 3 | AF4: 2 | AG4: 1 | AH4: 0
A5: 0x000 | B5: VERSION | C5: VERSION
A6: 0x004 | B6: CONTROL | C6: Reserved | AF6: LISTEN_ONLY | AG6: LOOPBACK | AH6: CAN_ENABLE
A7: 0x008 | B7: STATUS | C7: Reserved | X7: RX_OVERFLOW | Y7: BIT_ERROR | Z7: FORM_ERROR | AA7: STUFF_ERROR | AB7: CRC_ERROR | AC7: ACK_ERROR | AD7: ARB_LOST | AE7: RX_FIFO_FULL | AF7: RX_AVAILABLE | AG7: TX_DONE | AH7: TX_BUSY
A8: 0x00C | B8: ERROR_STATUS | C8: Reserved | AA8: LAST_ERROR_TYPE | AE8: LAST_ERROR_VALID | AF8: RECOVERY_ACTIVE | AG8: ERROR_STATE
A9: 0x010 | B9: BRP | C9: BRP
A10: 0x014 | B10: SEGMENTS | C10: Reserved | K10: PHASE_SEG2 | S10: PHASE_SEG1 | AA10: PROP_SEG
A11: 0x018 | B11: SJW_CONTROL | C11: Reserved | AE11: SJW
A12: 0x01C | B12: TX_ID | C12: not listed | F12: TX_IDENTIFIER
A13: 0x020 | B13: TX_CTRL | C13: Reserved | AC13: TX_DLC | AG13: TX_RTR | AH13: TX_IDE
A14: 0x024 | B14: TX_DATA_LO | C14: TX_DATA[31:0]
A15: 0x028 | B15: TX_DATA_HI | C15: TX_DATA[63:32]
A16: 0x02C | B16: TX_COMMAND | C16: Reserved | AH16: TX_START
A17: 0x030 | B17: TX_STATUS | C17: Reserved | AC17: TX_ERROR | AD17: TX_ARBITRATION_LOST | AE17: TX_ACK_RECEIVED | AF17: TX_DONE | AG17: TX_BUSY | AH17: TX_PENDING
A18: 0x034 | B18: RX_STATUS | C18: Reserved | X18: RX_OVERFLOW | Y18: RX_FIFO_FULL | Z18: RX_EMPTY | AA18: FIFO_COUNT
A19: 0x038 | B19: RX_ID | C19: not listed | F19: RX_IDENTIFIER
A20: 0x03C | B20: RX_CTRL | C20: Reserved | AC20: RX_DLC | AG20: RX_RTR | AH20: RX_IDE
A21: 0x040 | B21: RX_DATA_LO | C21: RX_DATA[31:0]
A22: 0x044 | B22: RX_DATA_HI | C22: RX_DATA[63:32]
A23: 0x048 | B23: RX_COMMAND | C23: Reserved | AH23: RX_POP
A24: 0x04C | B24: FILTER0_ID | C24: not listed | F24: FILTER0_ID
A25: 0x050 | B25: FILTER0_MASK | C25: not listed | F25: FILTER0_MASK
A26: 0x054 | B26: FILTER0_CTRL | C26: Reserved | AG26: FILTER0_IDE | AH26: FILTER0_ENABLE
A27: 0x058 | B27: FILTER1_ID | C27: not listed | F27: FILTER1_ID
A28: 0x05C | B28: FILTER1_MASK | C28: not listed | F28: FILTER1_MASK
A29: 0x060 | B29: FILTER1_CTRL | C29: Reserved | AG29: FILTER1_IDE | AH29: FILTER1_ENABLE
A30: 0x064 | B30: TEC | C30: not listed | Z30: TEC
A31: 0x068 | B31: REC | C31: not listed | AA31: REC
A33: Where the spec table lists no field for a bit range (e.g. ID registers above bit 28, TEC above bit 8), the range is shown as not listed rather than assumed reserved.

Sheet Rules & Notes
A1: Access rules, encodings and register-related limitations
A3: Bus interface rules (Section 5)
A4: Topic | B4: Rule | C4: Source
A5: Bus | B5: APB4 slave (can_apb_slave), ADDR_WIDTH = 12. All registers are 32 bits wide and word aligned; offsets 0x000 to 0x068 (27 registers). | C5: Section 5, 9
A6: Write strobes | B6: Writes are byte-strobe (PSTRB) qualified. | C6: Section 5
A7: Wait states | B7: PREADY is always asserted in the same cycle (zero-wait-state slave). | C7: Section 5, 10
A8: Unmapped addresses | B8: Read as 0; writes are accepted with no effect and no error. | C8: Section 5
A9: PSLVERR | B9: Asserted, and the write discarded (register unchanged), in exactly the cases listed in the next table. | C9: Section 5
A10: Reserved bits | B10: Listed as RO and read as 0. | C10: Section 5
A11: Interrupts | B11: No interrupt output: all status, error and RX-available information is polled through these registers. | C11: Section 10
A13: PSLVERR cases (write discarded, register unchanged)
A14: Register | B14: Condition | C14: Source
A15: CONTROL | B15: A write that clears CAN_ENABLE while a frame is in progress (tx_busy). | C15: Section 5
A16: CONTROL | B16: A single write that sets LOOPBACK and LISTEN_ONLY together. | C16: Section 5
A17: BRP | B17: Any write while CAN_ENABLE = 1. | C17: Section 5
A18: SEGMENTS | B18: Whole register rejected while CAN_ENABLE = 1. | C18: Section 5
A19: SJW_CONTROL | B19: Any write while CAN_ENABLE = 1. | C19: Section 5
A20: FILTER0_ID, FILTER0_MASK, FILTER0_CTRL | B20: Any write while CAN_ENABLE = 1 (CTRL: whole register). | C20: Section 5, 6.10
A21: FILTER1_ID, FILTER1_MASK, FILTER1_CTRL | B21: Any write while CAN_ENABLE = 1 (CTRL: whole register). | C21: Section 5, 6.10
A23: Encodings
A24: Field | B24: Encoding | C24: Source
A25: ERROR_STATUS.ERROR_STATE | B25: 0 = Error Active, 1 = Error Passive, 2 = Bus Off, 3 = unused. | C25: Section 5
A26: ERROR_STATUS.LAST_ERROR_TYPE | B26: 0 none, 1 bit error, 2 stuff error, 3 CRC error, 4 form error, 5 ACK error, 6 arbitration lost (an event, not a CAN error). | C26: Section 5, 6.8
A27: TX_ID / RX_ID identifier | B27: IDE = 0: bits [10:0] are the standard 11-bit ID. IDE = 1: all 29 bits; [28:18] = 11-bit base ID, [17:0] = 18-bit extension. | C27: Section 5
A28: Acceptance filter mask | B28: 1 = compare this identifier bit, 0 = don't care. Both filters disabled: every valid frame is accepted; otherwise a frame passes if either enabled filter matches IDE and (ID AND mask). | C28: Section 5, 6.10
A30: Data byte ordering (Section 6.2)
A31: Topic | B31: Rule | C31: Source
A32: TX_DATA byte order | B32: DLC-relative and right-justified in the 64-bit register: for DLC = N, the first byte transmitted is TX_DATA[(8N-1):(8N-8)] and the last byte transmitted is always TX_DATA[7:0]. | C32: Section 6.2
A33: Example | B33: DLC = 3: the bytes sent are TX_DATA[23:16], TX_DATA[15:8], TX_DATA[7:0], in that order. | C33: Section 6.2
A34: RX_DATA byte order | B34: Data-byte capture follows the same DLC-relative, right-justified convention as the transmit path. | C34: Section 6.2
A36: Sticky bits and pulses
A37: Bit | B37: Behaviour | C37: Source
A38: STATUS.TX_DONE, TX_STATUS.TX_DONE / TX_ACK_RECEIVED / TX_ARBITRATION_LOST / TX_ERROR | B38: Sticky; cleared by writing TX_COMMAND.TX_START (a write of 1 submits the frame and starts a new attempt). | C38: Section 5
A39: STATUS.RX_OVERFLOW, RX_STATUS.RX_OVERFLOW | B39: Sticky; set when a frame arrives while the RX FIFO is full; never cleared by hardware, only by a CAN_CLK-domain reset. | C39: Section 5, 10
A40: STATUS[9:4] (ARB_LOST, ACK_ERROR, CRC_ERROR, STUFF_ERROR, FORM_ERROR, BIT_ERROR) | B40: Live single-cycle pulses synchronized into the pclk domain, not latched; a polling host can miss them. ERROR_STATUS.LAST_ERROR_TYPE latches only the single most recent error / event. | C40: Section 10
A41: TX_COMMAND.TX_START, RX_COMMAND.RX_POP | B41: Write-only, self-clearing, read as 0. RX_POP should be written only after RX_ID / RX_CTRL / RX_DATA_* have been read. | C41: Section 5
A43: Typical access sequences (derived from the rules above)
A44: Task | B44: Sequence | C44: Basis
A45: Configure | B45: With CAN_ENABLE = 0: program BRP, SEGMENTS, SJW_CONTROL and the filter registers, then set CAN_ENABLE = 1 (plus LOOPBACK or LISTEN_ONLY if needed, not both). | C45: These registers reject writes while CAN_ENABLE = 1; BRP must be programmed before enabling
A46: Transmit | B46: Write TX_ID, TX_CTRL (DLC 0-8), TX_DATA_LO / HI; write 1 to TX_COMMAND.TX_START; poll TX_STATUS for TX_DONE or TX_ERROR before staging the next frame. | C46: Single TX descriptor, no queue (Section 10)
...
